<?xml version="1.0" encoding="UTF-8"?>
<!-- Generated by org.testng.reporters.JUnitReportReporter -->
<testsuite hostname="Anitha" failures="0" tests="4" name="workingWithTestNg.ExpectedExeception" time="0.025" errors="1" timestamp="2023-09-07T14:03:54 BST" skipped="0">
  <testcase classname="workingWithTestNg.ExpectedExeception" name="printName" time="0.001"/>
  <testcase classname="workingWithTestNg.ExpectedExeception" name="test" time="0.001"/>
  <testcase classname="workingWithTestNg.ExpectedExeception" name="example" time="0.016"/>
  <testcase classname="workingWithTestNg.ExpectedExeception" name="print" time="0.007">
    <error message="
The exception was thrown with the wrong message: expected &quot;TESTING FAILED &quot; but got &quot;did not expect to find [0] but found [1]&quot;" type="org.testng.TestException">
      <![CDATA[org.testng.TestException: 
The exception was thrown with the wrong message: expected "TESTING FAILED " but got "did not expect to find [0] but found [1]"
at org.testng.internal.ExpectedExceptionsHolder.wrongException(ExpectedExceptionsHolder.java:70)
at org.testng.internal.Invoker.considerExceptions(Invoker.java:1279)
at org.testng.internal.Invoker.invokeMethod(Invoker.java:716)
at org.testng.internal.Invoker.invokeTestMethod(Invoker.java:821)
at org.testng.internal.Invoker.invokeTestMethods(Invoker.java:1128)
at org.testng.internal.TestMethodWorker.invokeTestMethods(TestMethodWorker.java:140)
at org.testng.internal.TestMethodWorker.run(TestMethodWorker.java:122)
at org.testng.TestRunner.privateRun(TestRunner.java:724)
at org.testng.TestRunner.run(TestRunner.java:574)
at org.testng.SuiteRunner.runTest(SuiteRunner.java:398)
at org.testng.SuiteRunner.runSequentially(SuiteRunner.java:392)
at org.testng.SuiteRunner.privateRun(SuiteRunner.java:354)
at org.testng.SuiteRunner.run(SuiteRunner.java:302)
at org.testng.SuiteRunnerWorker.runSuite(SuiteRunnerWorker.java:53)
at org.testng.SuiteRunnerWorker.run(SuiteRunnerWorker.java:96)
at org.testng.TestNG.runSuitesSequentially(TestNG.java:1142)
at org.testng.TestNG.runSuitesLocally(TestNG.java:1064)
at org.testng.TestNG.runSuites(TestNG.java:994)
at org.testng.TestNG.run(TestNG.java:962)
at org.testng.remote.AbstractRemoteTestNG.run(AbstractRemoteTestNG.java:115)
at org.testng.remote.RemoteTestNG.initAndRun(RemoteTestNG.java:251)
at org.testng.remote.RemoteTestNG.main(RemoteTestNG.java:77)
Caused by: java.lang.AssertionError: did not expect to find [0] but found [1]
at org.testng.Assert.fail(Assert.java:97)
at org.testng.Assert.failNotEquals(Assert.java:969)
at org.testng.Assert.assertEqualsImpl(Assert.java:136)
at org.testng.Assert.assertEquals(Assert.java:118)
at org.testng.Assert.assertEquals(Assert.java:839)
at org.testng.Assert.assertEquals(Assert.java:849)
at workingWithTestNg.ExpectedExeception.print(ExpectedExeception.java:14)
at java.base/jdk.internal.reflect.DirectMethodHandleAccessor.invoke(DirectMethodHandleAccessor.java:104)
at java.base/java.lang.reflect.Method.invoke(Method.java:578)
at org.testng.internal.MethodInvocationHelper.invokeMethod(MethodInvocationHelper.java:131)
at org.testng.internal.Invoker.invokeMethod(Invoker.java:687)
... 19 more
]]>
    </error>
  </testcase> <!-- print -->
</testsuite> <!-- workingWithTestNg.ExpectedExeception -->
