<?xml version="1.0" encoding="UTF-8"?>
<!-- Generated by org.testng.reporters.JUnitReportReporter -->
<testsuite hostname="Anitha" failures="1" tests="4" name="workingWithTestNg.Asserts_DependentMethod2_" time="0.029" errors="0" timestamp="2023-09-07T11:24:54 BST" skipped="0">
  <testcase classname="workingWithTestNg.Asserts_DependentMethod2_" name="example" time="0.002"/>
  <testcase classname="workingWithTestNg.Asserts_DependentMethod2_" name="test" time="0.015"/>
  <testcase classname="workingWithTestNg.Asserts_DependentMethod2_" name="printName" time="0.003"/>
  <testcase classname="workingWithTestNg.Asserts_DependentMethod2_" name="print" time="0.009">
    <failure message="did not expect to find [0] but found [1]" type="java.lang.AssertionError">
      <![CDATA[java.lang.AssertionError: did not expect to find [0] but found [1]
at org.testng.Assert.fail(Assert.java:97)
at org.testng.Assert.failNotEquals(Assert.java:969)
at org.testng.Assert.assertEqualsImpl(Assert.java:136)
at org.testng.Assert.assertEquals(Assert.java:118)
at org.testng.Assert.assertEquals(Assert.java:839)
at org.testng.Assert.assertEquals(Assert.java:849)
at workingWithTestNg.Asserts_DependentMethod2_.print(Asserts_DependentMethod2_.java:12)
at java.base/jdk.internal.reflect.DirectMethodHandleAccessor.invoke(DirectMethodHandleAccessor.java:104)
at java.base/java.lang.reflect.Method.invoke(Method.java:578)
at org.testng.internal.MethodInvocationHelper.invokeMethod(MethodInvocationHelper.java:131)
at org.testng.internal.Invoker.invokeMethod(Invoker.java:687)
at org.testng.internal.Invoker.invokeTestMethod(Invoker.java:821)
at org.testng.internal.Invoker.invokeTestMethods(Invoker.java:1128)
at org.testng.internal.TestMethodWorker.invokeTestMethods(TestMethodWorker.java:140)
at org.testng.internal.TestMethodWorker.run(TestMethodWorker.java:122)
at org.testng.TestRunner.privateRun(TestRunner.java:724)
at org.testng.TestRunner.run(TestRunner.java:574)
at org.testng.SuiteRunner.runTest(SuiteRunner.java:398)
at org.testng.SuiteRunner.runSequentially(SuiteRunner.java:392)
at org.testng.SuiteRunner.privateRun(SuiteRunner.java:354)
at org.testng.SuiteRunner.run(SuiteRunner.java:302)
at org.testng.SuiteRunnerWorker.runSuite(SuiteRunnerWorker.java:53)
at org.testng.SuiteRunnerWorker.run(SuiteRunnerWorker.java:96)
at org.testng.TestNG.runSuitesSequentially(TestNG.java:1142)
at org.testng.TestNG.runSuitesLocally(TestNG.java:1064)
at org.testng.TestNG.runSuites(TestNG.java:994)
at org.testng.TestNG.run(TestNG.java:962)
at org.testng.remote.AbstractRemoteTestNG.run(AbstractRemoteTestNG.java:115)
at org.testng.remote.RemoteTestNG.initAndRun(RemoteTestNG.java:251)
at org.testng.remote.RemoteTestNG.main(RemoteTestNG.java:77)
]]>
    </failure>
  </testcase> <!-- print -->
</testsuite> <!-- workingWithTestNg.Asserts_DependentMethod2_ -->
